Processing benchmark results...
Traceback (most recent call last):
  File "/root/genral-python-scripts/benchmarking/membenchmark1/./membench3.py", line 70, in <module>
    hostname = parts[0].split("=")[1]
               ~~~~~~~~~~~~~~~~~~~^^^
IndexError: list index out of range


Traceback (most recent call last):
  File "/root/genral-python-scripts/benchmarking/membenchmark1/./memory5.py", line 82, in <module>
    json_data.append(json.loads(line.strip().split("msg: ", 1)[1]))
                                ~~~~~~~~~~~~~~~~~~~~~~~~~~~~~~^^^
IndexError: list index out of range

Traceback (most recent call last):
  File "/root/genral-python-scripts/benchmarking/membenchmark1/./memory6.py", line 96, in <module>
    df[numeric_cols] = df[numeric_cols].apply(pd.to_numeric, errors='coerce')
                       ~~^^^^^^^^^^^^^^
  File "/usr/local/python312/lib/python3.12/site-packages/pandas/core/frame.py", line 4108, in __getitem__
    indexer = self.columns._get_indexer_strict(key, "columns")[1]
              ^^^^^^^^^^^^^^^^^^^^^^^^^^^^^^^^^^^^^^^^^^^^^^^^
  File "/usr/local/python312/lib/python3.12/site-packages/pandas/core/indexes/base.py", line 6200, in _get_indexer_strict
    self._raise_if_missing(keyarr, indexer, axis_name)
  File "/usr/local/python312/lib/python3.12/site-packages/pandas/core/indexes/base.py", line 6249, in _raise_if_missing
    raise KeyError(f"None of [{key}] are in the [{axis_name}]")
KeyError: "None of [Index(['cpu_cores', 'memory_mb', 'read_total_events', 'read_events_per_sec',\n       'write_total_events', 'write_events_per_sec'],\n      dtype='object')] are in the [columns]"
